<?xml version="1.0" encoding="UTF-8"?>
<sdf version='1.6'>
  <model name='motoman_gripper'>
    <pose>0 0 0 0 0 0</pose>
    <link name='motoman_link_t'>
      <pose frame=''>0 0 0 3.14159 0 0</pose>
      <kinematic>true</kinematic>
      <!--inertial>
        <pose frame=''>0 0.069404 0 0 0 0</pose>
        <mass>5</mass>
        <inertia>
          <ixx>1</ixx>
          <ixy>0</ixy>
          <ixz>0</ixz>
          <iyy>1</iyy>
          <iyz>0</iyz>
          <izz>1</izz>
        </inertia>
      </inertial-->
      <collision name='motoman_link_t_collision'>
        <pose frame=''>0 0 0 0 0 0</pose>
        <geometry>
          <mesh>
            <scale>1 1 1</scale>
            <uri>model://motoman_gripper/meshes/motoman_link_t.STL</uri>
          </mesh>
        </geometry>
      </collision>
      <visual name='motoman_link_t_visual'>
        <pose frame=''>0 0 0 0 0 0</pose>
        <geometry>
          <mesh>
            <scale>1 1 1</scale>
            <uri>model://motoman_gripper/meshes/motoman_link_t.STL</uri>
          </mesh>
        </geometry>
        <material>
          <script>
            <name>Gazebo/Blue</name>
            <uri>file://media/materials/scripts/gazebo.material</uri>
          </script>
        </material>
      </visual>
      <gravity>1</gravity>
      <velocity_decay/>
    </link>

    <link name='motoman_finger_1'>
      <pose frame=''>0.0225 0 -0.162 1.5708 3.14159 3.14159</pose>
      <inertial>
        <pose frame=''>0.022998 0.021681 0 0 0 0</pose>
        <mass>0.1</mass>
        <inertia>
          <ixx>0.1</ixx>
          <ixy>0</ixy>
          <ixz>0</ixz>
          <iyy>0.1</iyy>
          <iyz>0</iyz>
          <izz>0.1</izz>
        </inertia>
      </inertial>
      <collision name='motoman_finger_1_collision'>
        <pose frame=''>0 0 0 0 0 0</pose>
        <geometry>
          <mesh>
            <scale>1 1 1</scale>
            <uri>model://motoman_gripper/meshes/motoman_finger_1.STL</uri>
          </mesh>
        </geometry>
      </collision>
      <visual name='motoman_finger_1_visual'>
        <pose frame=''>0 0 0 0 -0 0</pose>
        <geometry>
          <mesh>
            <scale>1 1 1</scale>
            <uri>model://motoman_gripper/meshes/motoman_finger_1.STL</uri>
          </mesh>
        </geometry>
      </visual>
    </link>
    <joint name='motoman_prism_1' type='prismatic'>
      <child>motoman_finger_1</child>
      <parent>motoman_link_t</parent>
      <axis>
        <xyz>-1 0 0</xyz>
        <limit>
          <lower>0</lower>
          <upper>0.0225</upper>
          <effort>1000</effort>
          <velocity>1000</velocity>
        </limit>
        <dynamics>
          <spring_reference>0</spring_reference>
          <spring_stiffness>0</spring_stiffness>
        </dynamics>
        <use_parent_model_frame>1</use_parent_model_frame>
      </axis>
    </joint>
    <link name='motoman_finger_2'>
      <pose frame=''>-0.0225 0 -0.162 1.5708 3.14159 0</pose>
      <inertial>
        <pose frame=''>0.022998 0.021681 0 0 0 0</pose>
        <mass>0.1</mass>
        <inertia>
          <ixx>0.1</ixx>
          <ixy>0</ixy>
          <ixz>0</ixz>
          <iyy>0.1</iyy>
          <iyz>0</iyz>
          <izz>0.1</izz>
        </inertia>
      </inertial>
      <collision name='motoman_finger_2_collision'>
        <pose frame=''>0 0 0 0 0 0</pose>
        <geometry>
          <mesh>
            <scale>1 1 1</scale>
            <uri>model://motoman_gripper/meshes/motoman_finger_2.STL</uri>
          </mesh>
        </geometry>
      </collision>
      <visual name='motoman_finger_2_visual'>
        <pose frame=''>0 0 0 0 0 0</pose>
        <geometry>
          <mesh>
            <scale>1 1 1</scale>
            <uri>model://motoman_gripper/meshes/motoman_finger_2.STL</uri>
          </mesh>
        </geometry>
      </visual>
    </link>
    <joint name='motoman_prism_2' type='prismatic'>
      <child>motoman_finger_2</child>
      <parent>motoman_link_t</parent>
      <axis>
        <xyz>1 0 0</xyz>
        <limit>
          <lower>0</lower>
          <upper>0.0225</upper>
          <effort>1000</effort>
          <velocity>1000</velocity>
        </limit>
        <dynamics>
          <spring_reference>0</spring_reference>
          <spring_stiffness>0</spring_stiffness>
        </dynamics>
        <use_parent_model_frame>1</use_parent_model_frame>
      </axis>
    </joint>

  </model>
</sdf>
